# 优雅的异常处理

讨论地址是：[优雅的异常处理· Issue #1 · qianxin-fe/weekly](https://github.com/qianxin-fe/weekly/issues/1)

最近在做 CodeReview 的时候发了很多未处理错误的情况

其实大多数的问题都发生在 `async await` 这个语法的使用上. 有许多同学不太理解 `async` 函数返回了一个 `Promise` 到底意味着什么. 只是知道它返回了而已.

## 什么是异常

正如我们经常使用的

```jsx
throw TypeError('this is type error!')
throw new TypeError('this is new type error!')

throw 'this is error'
```

这是我们手动创建并抛出的异常. 那些经常让你抓狂的是浏览器或是解释器抛出的异常. 这里值得说一下的是: 请不要采取第三种或类似第三种的方式, 你总是需要抛出一个正确的错误对象.

## 抛出异常发生了什么

异常被抛出后, 就好像我们熟知的事件流. 它会在当前程序栈中冒泡, 除非在某个阶段捕获(处理)了它.  一旦它到达最外层而又没有处理, 程序就会崩溃.  这也是好多框架都提供一个兜底错误处理的原因.

在 `Devtools` 里就会看见类似的输出:

```jsx
index.html:57 Uncaught TypeError: the day is string!
    at c (index.html:57)
    at b (index.html:56)
    at a (index.html:55)
    at main (index.html:54)
    at index.html:58
```

能较清晰的看到一个调用栈.

PS: 这也是要求 **throw 一个正确对象** 的原因.

## 同步错误

简单来说就是当前执行栈里发生的错误, 也就是我们常说的, 执行同步代码时产生的错误.

```jsx
function println(content) {
	if (typeof content !== 'string') {
		throw TypeError('Wrong type');
	}
	console.log(content);
}
```

最常规的解决方式 `try...catch...finally` 

```jsx
try {
	println(1);
} catch (error) {
	console.log('error');
}
// ... other code
```

## 异步错误

如果错误都和上面的例子一样, 那处理错误就很简单. 可是JS是一门以异步为核心的语言. 简单模拟一个异步的情况.

```jsx
function failRequest() {
	window.setTimeout(() => throw Error('Someting?'), 1000);
}
```

继续理想的错误处理

```jsx
try {
	failRequest();
} catch (error) {
	console.log(error);
}
```

```jsx
VM1424:2 Uncaught Error: Someting?
    at <anonymous>:2:34
```

然而并没有捕获到这个错误. 说到底 `try/...catch` **只能捕获同步的错误**. 典型的还有监听 *DOM* 的事件, 只不过现在都是基于某框架在开发, 不会再碰见这个问题了而已.

那为什么呢?

如果理解了 **抛出异常发生了什么** 那个段落, 你就发现这个异步里发生的错误和 `try...catch` 的根本不在一个执行栈里, 冒泡到顶部也不会找到, 所以报错了.

这么看来这样的错误想要处理似乎只有把 `try...catch` 给挪到同一个级别去. 或者用 `Promise` 这样的API进行一次包装.

## async/await

说了到 `Promise`  才到了这个ES7的语法, 绕了一大圈. 这里定义几个异步函数

```jsx
async function request1() {
	return new Promise((_, reject) => {
		window.setTimeout(reject, 2000);
	});
}

async function request2() {
	throw Error('request error');
	await fetch('/api/users');
	console.log('Cool!');
}

async function main() {
	try{
		request1();
		request2();
	} catch (error) {
		console.error(error);
	}
}
```

`main` 这个函数看起来写得很稳健. 但它还是会报错(没有捕获到), 而且还是两个错.

```jsx
VM119:8 Uncaught (in promise) Error: request error
    at request2 (<anonymous>:8:8)
    at main (<anonymous>:16:3)
    at <anonymous>:1:1

1751487:1 Uncaught (in promise) undefined
```

原理是类似的, 他们两个不在一条线上. 这个环节里修正很简单

```jsx
await request1();
await request2();
```

这么看来调用 async 函数的地方不加 await 那就是在耍流氓....

## 每个 await 都必须加 try...catch?

先说结论, 如果你的函数总是能返回一个正确的值, 就不用.

```jsx
async function request() {
  return 'request';
}

async function request1() {
  try {
    throw Error('request1 error');
    return 'KPL';
  } catch (error) {
    return 'request1'
  }
}
async function main() {
  const r = await request();
  const r1 = await request1();
  console.log(r, r1);
}

main();
```

这里重申一个大家都熟悉的概念,  `async` 函数返回一个Promise. 其中, return 的东西将会解释为 resolve的内容. 如果有异常将会成为底层Promise reject的原因. 基于这个情况也可以这样处理

```jsx
async function request() {
  return 'request';
}

async function request1() {
  throw Error('request1 error');
}
async function main() {
  const r = await request();
  const r1 = await request1().catch(() => 'request1 value');
  console.log(r, r1);
}

main() //request,  request1 value
```

这行代码就好像在表达, 如果错了就请用  *request1 value* 这个字符串的感觉:

```jsx
const r1 = await request1().catch(() => 'request1 value');
```